<robot xmlns:xacro="http://www.ros.org/wiki/xacro" name="robot_name">
    <link name="base_link">
    </link>
    <link name="p_0">
    <inertial>
            <origin xyz="0.0 0.0 0.250" rpy="0.0 0.0 0.0"/>
            <mass value="1.0"/>
            <inertia ixx="1.0" ixy="1.0" ixz="1.0" iyy="1.0" iyz="1.0" izz="1.0"/>
        </inertial>
    <visual>
        <origin xyz="0.0 0.0 0.250" rpy="0.0 0.0 0.0"/>
        <geometry>
            <box size="0.50 0.50 0.50"/>
        </geometry>
    </visual>
    <collision>
            <origin xyz="0.0 0.0 0.250" rpy="0.0 0.0 0.0"/>
            <geometry>
                <box size="0.50 0.50 0.50"/>
            </geometry>
        </collision>
    </link>
    <link name="p_1">
        <inertial>
            <origin xyz="0.0 0.0 0.50" rpy="0.0 0.0 0.0"/>
            <mass value="1.0"/>
            <inertia ixx="1.0" ixy="1.0" ixz="1.0" iyy="1.0" iyz="1.0" izz="1.0"/>
        </inertial>
        <visual name="">
            <origin xyz="0.0 0.0 0.50" rpy="0.0 0.0 0.0"/>
            <geometry>
                <box size="0.250 0.250 1.0"/>
            </geometry>

        </visual>
        <collision>
            <origin xyz="0.0 0.0 0.50" rpy="0.0 0.0 0.0"/>
            <geometry>
                <box size="0.250 0.250 1.0"/>
            </geometry>
        </collision>
    </link>
    <link name="p_2">
        <inertial>
            <origin xyz="0.0 0.1250 0.50" rpy="0.0 0.0 0.0"/>
            <mass value="1.0"/>
            <inertia ixx="1.0" ixy="1.0" ixz="1.0" iyy="1.0" iyz="1.0" izz="1.0"/>
        </inertial>
        <visual name="">
            <origin xyz="0.0 0.125 0.50" rpy="0.0 0.0 0.0"/>
            <geometry>
                <box size="0.250 0.250 1.0"/>
            </geometry>
        </visual>
        <collision>
            <origin xyz="0.0 0.1250 0.50" rpy="0.0 0.0 0.0"/>
            <geometry>
                <box size="0.250 0.250 1.0"/>
            </geometry>
        </collision>

    </link>
    <link name="p_3">
        <inertial>
            <origin xyz="0.0 -0.1250 0.50" rpy="0.0 0.0 0.0"/>
            <mass value="1.0"/>
            <inertia ixx="1.0" ixy="1.0" ixz="1.0" iyy="1.0" iyz="1.0" izz="1.0"/>
        </inertial>
        <visual name="">
            <origin xyz="0.0 -0.125 0.50" rpy="0.0 0.0 0.0"/>
            <geometry>
                <box size="0.250 0.250 1.0"/>
            </geometry>
        </visual>
        <collision>
            <origin xyz="0.0 -0.1250 0.50" rpy="0.0 0.0 0.0"/>
            <geometry>
                <box size="0.250 0.250 1.0"/>
            </geometry>
        </collision>
    </link>
    <link name="g_0">
        <inertial>
            <origin xyz="0.0 0.0 0.125" rpy="0.0 0.0 0.0"/>
            <mass value="1.0"/>
            <inertia ixx="1.0" ixy="1.0" ixz="1.0" iyy="1.0" iyz="1.0" izz="1.0"/>
        </inertial>
        <visual name="">
            <origin xyz="0.0 0.0 0.1250" rpy="0.0 0.0 0.0"/>
            <geometry>
                <box size="0.150 0.150 0.250"/>
            </geometry>
            <material name="">
                <color rgba="1.0 1.0 0.0 1.0"/>
                <texture filename=""/>
            </material>
        </visual>
        <collision>
            <origin xyz="0.0 0.0 0.1250" rpy="0.0 0.0 0.0"/>
            <geometry>
                <box size="0.150 0.150 0.250"/>
            </geometry>
        </collision>
    </link>
    <link name="g_01">
        <inertial>
            <origin xyz="0.0 0.0 0.0750" rpy="0.0 0.0 0.0"/>
            <mass value="1.0"/>
            <inertia ixx="0.0" ixy="0.0" ixz="0.0" iyy="0.0" iyz="0.0" izz="0.0"/>
        </inertial>
        <visual name="">
            <origin xyz="0.0 0.0 0.0750" rpy="0.0 0.0 0.0"/>
            <geometry>
                <box size="0.250 0.250 0.150"/>
            </geometry>
            <material name="">
                <color rgba="1.0 0.0 0.0 1.0"/>
                <texture filename=""/>
            </material>
        </visual>
        <collision>
            <origin xyz="0.0 0.0 0.0750" rpy="0.0 0.0 0.0"/>
            <geometry>
                <box size="0.250 0.250 0.150"/>
            </geometry>
        </collision>
    </link>
    <link name="g_r">
        <inertial>
            <origin xyz="0.0 0.0 0.05" rpy="0.0 0.0 0.0"/>
            <mass value="1.0"/>
            <inertia ixx="0.0" ixy="0.0" ixz="0.0" iyy="0.0" iyz="0.0" izz="0.0"/>
        </inertial>
        <visual name="">
            <origin xyz="0.0 0.0 0.05" rpy="0.0 0.0 0.0"/>
            <geometry>
                <box size="0.1 0.05 0.2"/>
            </geometry>
            <material name="">
                <color rgba="1.0 1.0 1.0 1.0"/>
                <texture filename=""/>
            </material>
        </visual>
        <collision>
            <origin xyz="0.0 0.0 0.05" rpy="0.0 0.0 0.0"/>
            <geometry>
                <box size="0.1 0.05 0.2"/>
            </geometry>
        </collision>
    </link>
    <link name="g_l">
        <inertial>
            <origin xyz="0.0 0.0 0.05" rpy="0.0 0.0 0.0"/>
            <mass value="1.0"/>
            <inertia ixx="0.0" ixy="0.0" ixz="0.0" iyy="0.0" iyz="0.0" izz="0.0"/>
        </inertial>
        <visual name="">
            <origin xyz="0.0 0.0 0.05" rpy="0.0 0.0 0.0"/>
            <geometry>
                <box size="0.1 -0.05 0.20"/>
            </geometry>
            <material name="">
                <color rgba="1.0 1.0 1.0 1.0"/>
                <texture filename=""/>
            </material>
        </visual>
        <collision>
            <origin xyz="0.0 0.0 0.05" rpy="0.0 0.0 0.0"/>
            <geometry>
                <box size="0.10 -0.05 0.20"/>
            </geometry>
        </collision>
    </link>

    <joint name="fixed" type="fixed">
        <origin xyz="0.0 0.0 0.0" rpy="0.0 0.0 0.0"/>
        <parent link="base_link"/>
        <child link="p_0"/>
        <axis xyz="0.0 0.0 1.0"/>
        <limit lower="0.0" upper="0.0" effort="0.0" velocity="0.0"/>
    </joint>
    <joint name="base" type="revolute">
        <origin xyz="0.0 0.0 0.50" rpy="0.0 0.0 0.0"/>
        <parent link="p_0"/>
        <child link="p_1"/>
        <axis xyz="0.0 0.0 1.0"/>
        <limit lower="0.0" upper="3.140" effort="0.0" velocity="0.0"/>
    </joint>
    <joint name="revo" type="revolute">
        <origin xyz="0.0 0.1250 0.8" rpy="0.0 0.0 0.0"/>
        <parent link="p_1"/>
        <child link="p_2"/>
        <axis xyz="0.0 1.0 0.0"/>
        <limit lower="0.0" upper="3.140" effort="0.0" velocity="0.0"/>
    </joint>
    <joint name="revo2" type="revolute">
        <origin xyz="0.0 0.0 0.8" rpy="0.0 0.0 0.0"/>
        <parent link="p_2"/>
        <child link="p_3"/>
        <axis xyz="0.0 1.0 0.0"/>
        <limit lower="0.0" upper="3.140" effort="0.0" velocity="0.0"/>
    </joint>
    <joint name="grip_0" type="revolute">
        <origin xyz="0.0 -0.1250 1.0" rpy="0.0 0.0 0.0"/>
        <parent link="p_3"/>
        <child link="g_0"/>
        <axis xyz="0.0 0.0 1.0"/>
        <limit lower="0.0" upper="3.140" effort="0.0" velocity="0.0"/>
    </joint>
    <joint name="grip_01" type="revolute">
        <origin xyz="0.0 0.0 0.250" rpy="0.0 0.0 0.0"/>
        <parent link="g_0"/>
        <child link="g_01"/>
        <axis xyz="0.0 1.0 0.0"/>
        <limit lower="-0.7850" upper="0.7850" effort="0.0" velocity="0.0"/>
    </joint>
    <joint name="grip_r" type="prismatic">
        <origin xyz="0.0 -0.075 0.20" rpy="0.0 0.0 0.0"/>
        <parent link="g_01"/>
        <child link="g_r"/>
        <axis xyz="0.0 1.0 0.0"/>
        <limit lower="0.0" upper="0.10" effort="0.0" velocity="0.0"/>
    </joint>
    <joint name="grip_l" type="prismatic">
        <origin xyz="0.0 0.075 0.20" rpy="0.0 0.0 0.0"/>
        <parent link="g_01"/>
        <child link="g_l"/>
        <axis xyz="0.0 1.0 0.0"/>
        <limit lower="-0.10" upper="0.0" effort="0.0" velocity="0.0"/>
    </joint>
</robot>